{
 "cells": [
  {
   "cell_type": "code",
   "execution_count": 12,
   "id": "61f22c4e",
   "metadata": {},
   "outputs": [],
   "source": [
    "import numpy as np\n",
    "import pandas as pd\n",
    "import tensorflow as tf\n",
    "from tensorflow.keras.models import Sequential, load_model\n",
    "from tensorflow.keras.layers import SimpleRNN, Dense, Embedding\n",
    "from tensorflow.keras.preprocessing.sequence import pad_sequences"
   ]
  },
  {
   "cell_type": "code",
   "execution_count": 13,
   "id": "da5b785d",
   "metadata": {},
   "outputs": [
    {
     "name": "stderr",
     "output_type": "stream",
     "text": [
      "C:\\Users\\User\\AppData\\Local\\Temp\\ipykernel_8280\\2693320996.py:3: VisibleDeprecationWarning: Creating an ndarray from ragged nested sequences (which is a list-or-tuple of lists-or-tuples-or ndarrays with different lengths or shapes) is deprecated. If you meant to do this, you must specify 'dtype=object' when creating the ndarray.\n",
      "  x_train = np.array(train_df['numerical_sequence'].apply(lambda x: [int(i) for i in x.split(',')]).tolist())\n"
     ]
    }
   ],
   "source": [
    "# Load training data\n",
    "train_df = pd.read_csv('data/tone_train.csv')\n",
    "x_train = np.array(train_df['numerical_sequence'].apply(lambda x: [int(i) for i in x.split(',')]).tolist())\n",
    "y_train = np.array(train_df['BERT_sentiment_score'])"
   ]
  },
  {
   "cell_type": "code",
   "execution_count": 14,
   "id": "c1305144",
   "metadata": {
    "scrolled": true
   },
   "outputs": [
    {
     "name": "stderr",
     "output_type": "stream",
     "text": [
      "C:\\Users\\User\\AppData\\Local\\Temp\\ipykernel_8280\\4200949146.py:3: VisibleDeprecationWarning: Creating an ndarray from ragged nested sequences (which is a list-or-tuple of lists-or-tuples-or ndarrays with different lengths or shapes) is deprecated. If you meant to do this, you must specify 'dtype=object' when creating the ndarray.\n",
      "  x_test = np.array(test_df['numerical_sequence'].apply(lambda x: [int(i) for i in x.split(',')]).tolist())\n"
     ]
    }
   ],
   "source": [
    "# Load test data\n",
    "test_df = pd.read_csv('data/tone_test.csv')\n",
    "x_test = np.array(test_df['numerical_sequence'].apply(lambda x: [int(i) for i in x.split(',')]).tolist())\n",
    "y_test = np.array(test_df['BERT_sentiment_score'])"
   ]
  },
  {
   "cell_type": "code",
   "execution_count": 15,
   "id": "48a90110",
   "metadata": {},
   "outputs": [],
   "source": [
    "# Pad sequences to a fixed length\n",
    "maxlen = 227\n",
    "x_train = tf.keras.preprocessing.sequence.pad_sequences(x_train, maxlen=maxlen, truncating='post')\n",
    "x_test = tf.keras.preprocessing.sequence.pad_sequences(x_test, maxlen=maxlen, truncating='post')"
   ]
  },
  {
   "cell_type": "code",
   "execution_count": 16,
   "id": "a564e8f9",
   "metadata": {},
   "outputs": [],
   "source": [
    "vocab_size = max(np.max(x_train), np.max(x_test)) + 1"
   ]
  },
  {
   "cell_type": "code",
   "execution_count": 17,
   "id": "6b240f08",
   "metadata": {},
   "outputs": [
    {
     "data": {
      "text/plain": [
       "38217"
      ]
     },
     "execution_count": 17,
     "metadata": {},
     "output_type": "execute_result"
    }
   ],
   "source": [
    "vocab_size"
   ]
  },
  {
   "cell_type": "code",
   "execution_count": 18,
   "id": "9df87c7b",
   "metadata": {},
   "outputs": [],
   "source": [
    "# Define the RNN model\n",
    "model = Sequential()\n",
    "model.add(Embedding(input_dim=vocab_size, output_dim=32, input_length=x_train.shape[1]))\n",
    "model.add(SimpleRNN(units=64))  # You can adjust the number of units as needed\n",
    "model.add(Dense(units=5, activation='softmax'))  # Assumes 5 output classes for classification"
   ]
  },
  {
   "cell_type": "code",
   "execution_count": 19,
   "id": "61d7516e",
   "metadata": {},
   "outputs": [
    {
     "name": "stdout",
     "output_type": "stream",
     "text": [
      "Epoch 1/10\n",
      "12461/12461 [==============================] - 442s 35ms/step - loss: 1.4516 - accuracy: 0.3887\n",
      "Epoch 2/10\n",
      "12461/12461 [==============================] - 485s 39ms/step - loss: 1.3704 - accuracy: 0.4499\n",
      "Epoch 3/10\n",
      "12461/12461 [==============================] - 459s 37ms/step - loss: 1.3060 - accuracy: 0.4885\n",
      "Epoch 4/10\n",
      "12461/12461 [==============================] - 447s 36ms/step - loss: 1.2546 - accuracy: 0.5217\n",
      "Epoch 5/10\n",
      "12461/12461 [==============================] - 451s 36ms/step - loss: 1.1911 - accuracy: 0.5454\n",
      "Epoch 6/10\n",
      "12461/12461 [==============================] - 443s 36ms/step - loss: 1.1297 - accuracy: 0.5796\n",
      "Epoch 7/10\n",
      "12461/12461 [==============================] - 438s 35ms/step - loss: 1.1021 - accuracy: 0.5843\n",
      "Epoch 8/10\n",
      "12461/12461 [==============================] - 443s 36ms/step - loss: 1.1608 - accuracy: 0.5625\n",
      "Epoch 9/10\n",
      "12461/12461 [==============================] - 437s 35ms/step - loss: 1.1145 - accuracy: 0.5833\n",
      "Epoch 10/10\n",
      "12461/12461 [==============================] - 412s 33ms/step - loss: 1.0702 - accuracy: 0.6083\n"
     ]
    },
    {
     "data": {
      "text/plain": [
       "<keras.callbacks.History at 0x1c0a750efa0>"
      ]
     },
     "execution_count": 19,
     "metadata": {},
     "output_type": "execute_result"
    }
   ],
   "source": [
    "# Compile the model\n",
    "model.compile(optimizer='adam', loss='sparse_categorical_crossentropy', metrics=['accuracy'])\n",
    "\n",
    "# Train the model\n",
    "model.fit(x_train, y_train, batch_size=1, epochs=10)"
   ]
  },
  {
   "cell_type": "code",
   "execution_count": null,
   "id": "d4550610",
   "metadata": {},
   "outputs": [],
   "source": [
    "# save the trained model\n",
    "model.save('RNN_sentiment_analysis_model.h5')"
   ]
  },
  {
   "cell_type": "code",
   "execution_count": 2,
   "id": "86fd1a46",
   "metadata": {},
   "outputs": [],
   "source": [
    "model = load_model('RNN_sentiment_analysis_model.h5')"
   ]
  },
  {
   "cell_type": "code",
   "execution_count": 7,
   "id": "a2fedcc1",
   "metadata": {},
   "outputs": [
    {
     "ename": "InvalidArgumentError",
     "evalue": "Graph execution error:\n\nDetected at node 'sequential/embedding/embedding_lookup' defined at (most recent call last):\n    File \"C:\\Users\\User\\anaconda3\\lib\\runpy.py\", line 197, in _run_module_as_main\n      return _run_code(code, main_globals, None,\n    File \"C:\\Users\\User\\anaconda3\\lib\\runpy.py\", line 87, in _run_code\n      exec(code, run_globals)\n    File \"C:\\Users\\User\\anaconda3\\lib\\site-packages\\ipykernel_launcher.py\", line 16, in <module>\n      app.launch_new_instance()\n    File \"C:\\Users\\User\\anaconda3\\lib\\site-packages\\traitlets\\config\\application.py\", line 846, in launch_instance\n      app.start()\n    File \"C:\\Users\\User\\anaconda3\\lib\\site-packages\\ipykernel\\kernelapp.py\", line 677, in start\n      self.io_loop.start()\n    File \"C:\\Users\\User\\anaconda3\\lib\\site-packages\\tornado\\platform\\asyncio.py\", line 199, in start\n      self.asyncio_loop.run_forever()\n    File \"C:\\Users\\User\\anaconda3\\lib\\asyncio\\base_events.py\", line 601, in run_forever\n      self._run_once()\n    File \"C:\\Users\\User\\anaconda3\\lib\\asyncio\\base_events.py\", line 1905, in _run_once\n      handle._run()\n    File \"C:\\Users\\User\\anaconda3\\lib\\asyncio\\events.py\", line 80, in _run\n      self._context.run(self._callback, *self._args)\n    File \"C:\\Users\\User\\anaconda3\\lib\\site-packages\\ipykernel\\kernelbase.py\", line 471, in dispatch_queue\n      await self.process_one()\n    File \"C:\\Users\\User\\anaconda3\\lib\\site-packages\\ipykernel\\kernelbase.py\", line 460, in process_one\n      await dispatch(*args)\n    File \"C:\\Users\\User\\anaconda3\\lib\\site-packages\\ipykernel\\kernelbase.py\", line 367, in dispatch_shell\n      await result\n    File \"C:\\Users\\User\\anaconda3\\lib\\site-packages\\ipykernel\\kernelbase.py\", line 662, in execute_request\n      reply_content = await reply_content\n    File \"C:\\Users\\User\\anaconda3\\lib\\site-packages\\ipykernel\\ipkernel.py\", line 360, in do_execute\n      res = shell.run_cell(code, store_history=store_history, silent=silent)\n    File \"C:\\Users\\User\\anaconda3\\lib\\site-packages\\ipykernel\\zmqshell.py\", line 532, in run_cell\n      return super().run_cell(*args, **kwargs)\n    File \"C:\\Users\\User\\anaconda3\\lib\\site-packages\\IPython\\core\\interactiveshell.py\", line 2863, in run_cell\n      result = self._run_cell(\n    File \"C:\\Users\\User\\anaconda3\\lib\\site-packages\\IPython\\core\\interactiveshell.py\", line 2909, in _run_cell\n      return runner(coro)\n    File \"C:\\Users\\User\\anaconda3\\lib\\site-packages\\IPython\\core\\async_helpers.py\", line 129, in _pseudo_sync_runner\n      coro.send(None)\n    File \"C:\\Users\\User\\anaconda3\\lib\\site-packages\\IPython\\core\\interactiveshell.py\", line 3106, in run_cell_async\n      has_raised = await self.run_ast_nodes(code_ast.body, cell_name,\n    File \"C:\\Users\\User\\anaconda3\\lib\\site-packages\\IPython\\core\\interactiveshell.py\", line 3309, in run_ast_nodes\n      if await self.run_code(code, result, async_=asy):\n    File \"C:\\Users\\User\\anaconda3\\lib\\site-packages\\IPython\\core\\interactiveshell.py\", line 3369, in run_code\n      exec(code_obj, self.user_global_ns, self.user_ns)\n    File \"C:\\Users\\User\\AppData\\Local\\Temp\\ipykernel_8280\\3094958203.py\", line 2, in <cell line: 2>\n      y_pred = model.predict(x_test)\n    File \"C:\\Users\\User\\anaconda3\\lib\\site-packages\\keras\\utils\\traceback_utils.py\", line 64, in error_handler\n      return fn(*args, **kwargs)\n    File \"C:\\Users\\User\\anaconda3\\lib\\site-packages\\keras\\engine\\training.py\", line 2033, in predict\n      tmp_batch_outputs = self.predict_function(iterator)\n    File \"C:\\Users\\User\\anaconda3\\lib\\site-packages\\keras\\engine\\training.py\", line 1845, in predict_function\n      return step_function(self, iterator)\n    File \"C:\\Users\\User\\anaconda3\\lib\\site-packages\\keras\\engine\\training.py\", line 1834, in step_function\n      outputs = model.distribute_strategy.run(run_step, args=(data,))\n    File \"C:\\Users\\User\\anaconda3\\lib\\site-packages\\keras\\engine\\training.py\", line 1823, in run_step\n      outputs = model.predict_step(data)\n    File \"C:\\Users\\User\\anaconda3\\lib\\site-packages\\keras\\engine\\training.py\", line 1791, in predict_step\n      return self(x, training=False)\n    File \"C:\\Users\\User\\anaconda3\\lib\\site-packages\\keras\\utils\\traceback_utils.py\", line 64, in error_handler\n      return fn(*args, **kwargs)\n    File \"C:\\Users\\User\\anaconda3\\lib\\site-packages\\keras\\engine\\training.py\", line 490, in __call__\n      return super().__call__(*args, **kwargs)\n    File \"C:\\Users\\User\\anaconda3\\lib\\site-packages\\keras\\utils\\traceback_utils.py\", line 64, in error_handler\n      return fn(*args, **kwargs)\n    File \"C:\\Users\\User\\anaconda3\\lib\\site-packages\\keras\\engine\\base_layer.py\", line 1014, in __call__\n      outputs = call_fn(inputs, *args, **kwargs)\n    File \"C:\\Users\\User\\anaconda3\\lib\\site-packages\\keras\\utils\\traceback_utils.py\", line 92, in error_handler\n      return fn(*args, **kwargs)\n    File \"C:\\Users\\User\\anaconda3\\lib\\site-packages\\keras\\engine\\sequential.py\", line 374, in call\n      return super(Sequential, self).call(inputs, training=training, mask=mask)\n    File \"C:\\Users\\User\\anaconda3\\lib\\site-packages\\keras\\engine\\functional.py\", line 458, in call\n      return self._run_internal_graph(\n    File \"C:\\Users\\User\\anaconda3\\lib\\site-packages\\keras\\engine\\functional.py\", line 596, in _run_internal_graph\n      outputs = node.layer(*args, **kwargs)\n    File \"C:\\Users\\User\\anaconda3\\lib\\site-packages\\keras\\utils\\traceback_utils.py\", line 64, in error_handler\n      return fn(*args, **kwargs)\n    File \"C:\\Users\\User\\anaconda3\\lib\\site-packages\\keras\\engine\\base_layer.py\", line 1014, in __call__\n      outputs = call_fn(inputs, *args, **kwargs)\n    File \"C:\\Users\\User\\anaconda3\\lib\\site-packages\\keras\\utils\\traceback_utils.py\", line 92, in error_handler\n      return fn(*args, **kwargs)\n    File \"C:\\Users\\User\\anaconda3\\lib\\site-packages\\keras\\layers\\core\\embedding.py\", line 199, in call\n      out = tf.nn.embedding_lookup(self.embeddings, inputs)\nNode: 'sequential/embedding/embedding_lookup'\nindices[13,225] = 34441 is not in [0, 34433)\n\t [[{{node sequential/embedding/embedding_lookup}}]] [Op:__inference_predict_function_518]",
     "output_type": "error",
     "traceback": [
      "\u001b[1;31m---------------------------------------------------------------------------\u001b[0m",
      "\u001b[1;31mInvalidArgumentError\u001b[0m                      Traceback (most recent call last)",
      "Input \u001b[1;32mIn [7]\u001b[0m, in \u001b[0;36m<cell line: 2>\u001b[1;34m()\u001b[0m\n\u001b[0;32m      1\u001b[0m \u001b[38;5;66;03m#TODO: predict not working because test data has words that are not included in the train data\u001b[39;00m\n\u001b[1;32m----> 2\u001b[0m y_pred \u001b[38;5;241m=\u001b[39m \u001b[43mmodel\u001b[49m\u001b[38;5;241;43m.\u001b[39;49m\u001b[43mpredict\u001b[49m\u001b[43m(\u001b[49m\u001b[43mx_test\u001b[49m\u001b[43m)\u001b[49m\n",
      "File \u001b[1;32m~\\anaconda3\\lib\\site-packages\\keras\\utils\\traceback_utils.py:67\u001b[0m, in \u001b[0;36mfilter_traceback.<locals>.error_handler\u001b[1;34m(*args, **kwargs)\u001b[0m\n\u001b[0;32m     65\u001b[0m \u001b[38;5;28;01mexcept\u001b[39;00m \u001b[38;5;167;01mException\u001b[39;00m \u001b[38;5;28;01mas\u001b[39;00m e:  \u001b[38;5;66;03m# pylint: disable=broad-except\u001b[39;00m\n\u001b[0;32m     66\u001b[0m   filtered_tb \u001b[38;5;241m=\u001b[39m _process_traceback_frames(e\u001b[38;5;241m.\u001b[39m__traceback__)\n\u001b[1;32m---> 67\u001b[0m   \u001b[38;5;28;01mraise\u001b[39;00m e\u001b[38;5;241m.\u001b[39mwith_traceback(filtered_tb) \u001b[38;5;28;01mfrom\u001b[39;00m \u001b[38;5;28mNone\u001b[39m\n\u001b[0;32m     68\u001b[0m \u001b[38;5;28;01mfinally\u001b[39;00m:\n\u001b[0;32m     69\u001b[0m   \u001b[38;5;28;01mdel\u001b[39;00m filtered_tb\n",
      "File \u001b[1;32m~\\anaconda3\\lib\\site-packages\\tensorflow\\python\\eager\\execute.py:54\u001b[0m, in \u001b[0;36mquick_execute\u001b[1;34m(op_name, num_outputs, inputs, attrs, ctx, name)\u001b[0m\n\u001b[0;32m     52\u001b[0m \u001b[38;5;28;01mtry\u001b[39;00m:\n\u001b[0;32m     53\u001b[0m   ctx\u001b[38;5;241m.\u001b[39mensure_initialized()\n\u001b[1;32m---> 54\u001b[0m   tensors \u001b[38;5;241m=\u001b[39m pywrap_tfe\u001b[38;5;241m.\u001b[39mTFE_Py_Execute(ctx\u001b[38;5;241m.\u001b[39m_handle, device_name, op_name,\n\u001b[0;32m     55\u001b[0m                                       inputs, attrs, num_outputs)\n\u001b[0;32m     56\u001b[0m \u001b[38;5;28;01mexcept\u001b[39;00m core\u001b[38;5;241m.\u001b[39m_NotOkStatusException \u001b[38;5;28;01mas\u001b[39;00m e:\n\u001b[0;32m     57\u001b[0m   \u001b[38;5;28;01mif\u001b[39;00m name \u001b[38;5;129;01mis\u001b[39;00m \u001b[38;5;129;01mnot\u001b[39;00m \u001b[38;5;28;01mNone\u001b[39;00m:\n",
      "\u001b[1;31mInvalidArgumentError\u001b[0m: Graph execution error:\n\nDetected at node 'sequential/embedding/embedding_lookup' defined at (most recent call last):\n    File \"C:\\Users\\User\\anaconda3\\lib\\runpy.py\", line 197, in _run_module_as_main\n      return _run_code(code, main_globals, None,\n    File \"C:\\Users\\User\\anaconda3\\lib\\runpy.py\", line 87, in _run_code\n      exec(code, run_globals)\n    File \"C:\\Users\\User\\anaconda3\\lib\\site-packages\\ipykernel_launcher.py\", line 16, in <module>\n      app.launch_new_instance()\n    File \"C:\\Users\\User\\anaconda3\\lib\\site-packages\\traitlets\\config\\application.py\", line 846, in launch_instance\n      app.start()\n    File \"C:\\Users\\User\\anaconda3\\lib\\site-packages\\ipykernel\\kernelapp.py\", line 677, in start\n      self.io_loop.start()\n    File \"C:\\Users\\User\\anaconda3\\lib\\site-packages\\tornado\\platform\\asyncio.py\", line 199, in start\n      self.asyncio_loop.run_forever()\n    File \"C:\\Users\\User\\anaconda3\\lib\\asyncio\\base_events.py\", line 601, in run_forever\n      self._run_once()\n    File \"C:\\Users\\User\\anaconda3\\lib\\asyncio\\base_events.py\", line 1905, in _run_once\n      handle._run()\n    File \"C:\\Users\\User\\anaconda3\\lib\\asyncio\\events.py\", line 80, in _run\n      self._context.run(self._callback, *self._args)\n    File \"C:\\Users\\User\\anaconda3\\lib\\site-packages\\ipykernel\\kernelbase.py\", line 471, in dispatch_queue\n      await self.process_one()\n    File \"C:\\Users\\User\\anaconda3\\lib\\site-packages\\ipykernel\\kernelbase.py\", line 460, in process_one\n      await dispatch(*args)\n    File \"C:\\Users\\User\\anaconda3\\lib\\site-packages\\ipykernel\\kernelbase.py\", line 367, in dispatch_shell\n      await result\n    File \"C:\\Users\\User\\anaconda3\\lib\\site-packages\\ipykernel\\kernelbase.py\", line 662, in execute_request\n      reply_content = await reply_content\n    File \"C:\\Users\\User\\anaconda3\\lib\\site-packages\\ipykernel\\ipkernel.py\", line 360, in do_execute\n      res = shell.run_cell(code, store_history=store_history, silent=silent)\n    File \"C:\\Users\\User\\anaconda3\\lib\\site-packages\\ipykernel\\zmqshell.py\", line 532, in run_cell\n      return super().run_cell(*args, **kwargs)\n    File \"C:\\Users\\User\\anaconda3\\lib\\site-packages\\IPython\\core\\interactiveshell.py\", line 2863, in run_cell\n      result = self._run_cell(\n    File \"C:\\Users\\User\\anaconda3\\lib\\site-packages\\IPython\\core\\interactiveshell.py\", line 2909, in _run_cell\n      return runner(coro)\n    File \"C:\\Users\\User\\anaconda3\\lib\\site-packages\\IPython\\core\\async_helpers.py\", line 129, in _pseudo_sync_runner\n      coro.send(None)\n    File \"C:\\Users\\User\\anaconda3\\lib\\site-packages\\IPython\\core\\interactiveshell.py\", line 3106, in run_cell_async\n      has_raised = await self.run_ast_nodes(code_ast.body, cell_name,\n    File \"C:\\Users\\User\\anaconda3\\lib\\site-packages\\IPython\\core\\interactiveshell.py\", line 3309, in run_ast_nodes\n      if await self.run_code(code, result, async_=asy):\n    File \"C:\\Users\\User\\anaconda3\\lib\\site-packages\\IPython\\core\\interactiveshell.py\", line 3369, in run_code\n      exec(code_obj, self.user_global_ns, self.user_ns)\n    File \"C:\\Users\\User\\AppData\\Local\\Temp\\ipykernel_8280\\3094958203.py\", line 2, in <cell line: 2>\n      y_pred = model.predict(x_test)\n    File \"C:\\Users\\User\\anaconda3\\lib\\site-packages\\keras\\utils\\traceback_utils.py\", line 64, in error_handler\n      return fn(*args, **kwargs)\n    File \"C:\\Users\\User\\anaconda3\\lib\\site-packages\\keras\\engine\\training.py\", line 2033, in predict\n      tmp_batch_outputs = self.predict_function(iterator)\n    File \"C:\\Users\\User\\anaconda3\\lib\\site-packages\\keras\\engine\\training.py\", line 1845, in predict_function\n      return step_function(self, iterator)\n    File \"C:\\Users\\User\\anaconda3\\lib\\site-packages\\keras\\engine\\training.py\", line 1834, in step_function\n      outputs = model.distribute_strategy.run(run_step, args=(data,))\n    File \"C:\\Users\\User\\anaconda3\\lib\\site-packages\\keras\\engine\\training.py\", line 1823, in run_step\n      outputs = model.predict_step(data)\n    File \"C:\\Users\\User\\anaconda3\\lib\\site-packages\\keras\\engine\\training.py\", line 1791, in predict_step\n      return self(x, training=False)\n    File \"C:\\Users\\User\\anaconda3\\lib\\site-packages\\keras\\utils\\traceback_utils.py\", line 64, in error_handler\n      return fn(*args, **kwargs)\n    File \"C:\\Users\\User\\anaconda3\\lib\\site-packages\\keras\\engine\\training.py\", line 490, in __call__\n      return super().__call__(*args, **kwargs)\n    File \"C:\\Users\\User\\anaconda3\\lib\\site-packages\\keras\\utils\\traceback_utils.py\", line 64, in error_handler\n      return fn(*args, **kwargs)\n    File \"C:\\Users\\User\\anaconda3\\lib\\site-packages\\keras\\engine\\base_layer.py\", line 1014, in __call__\n      outputs = call_fn(inputs, *args, **kwargs)\n    File \"C:\\Users\\User\\anaconda3\\lib\\site-packages\\keras\\utils\\traceback_utils.py\", line 92, in error_handler\n      return fn(*args, **kwargs)\n    File \"C:\\Users\\User\\anaconda3\\lib\\site-packages\\keras\\engine\\sequential.py\", line 374, in call\n      return super(Sequential, self).call(inputs, training=training, mask=mask)\n    File \"C:\\Users\\User\\anaconda3\\lib\\site-packages\\keras\\engine\\functional.py\", line 458, in call\n      return self._run_internal_graph(\n    File \"C:\\Users\\User\\anaconda3\\lib\\site-packages\\keras\\engine\\functional.py\", line 596, in _run_internal_graph\n      outputs = node.layer(*args, **kwargs)\n    File \"C:\\Users\\User\\anaconda3\\lib\\site-packages\\keras\\utils\\traceback_utils.py\", line 64, in error_handler\n      return fn(*args, **kwargs)\n    File \"C:\\Users\\User\\anaconda3\\lib\\site-packages\\keras\\engine\\base_layer.py\", line 1014, in __call__\n      outputs = call_fn(inputs, *args, **kwargs)\n    File \"C:\\Users\\User\\anaconda3\\lib\\site-packages\\keras\\utils\\traceback_utils.py\", line 92, in error_handler\n      return fn(*args, **kwargs)\n    File \"C:\\Users\\User\\anaconda3\\lib\\site-packages\\keras\\layers\\core\\embedding.py\", line 199, in call\n      out = tf.nn.embedding_lookup(self.embeddings, inputs)\nNode: 'sequential/embedding/embedding_lookup'\nindices[13,225] = 34441 is not in [0, 34433)\n\t [[{{node sequential/embedding/embedding_lookup}}]] [Op:__inference_predict_function_518]"
     ]
    }
   ],
   "source": [
    "#TODO: predict not working because test data has words that are not included in the train data\n",
    "y_pred = model.predict(x_test)"
   ]
  },
  {
   "cell_type": "code",
   "execution_count": null,
   "id": "85866e9d",
   "metadata": {},
   "outputs": [],
   "source": [
    "predicted_class = np.argmax(y_pred, axis=1)\n",
    "print(\"Predicted Class:\", predicted_class)"
   ]
  },
  {
   "cell_type": "code",
   "execution_count": 9,
   "id": "02c345d7",
   "metadata": {},
   "outputs": [
    {
     "name": "stdout",
     "output_type": "stream",
     "text": [
      "(12461, 227)\n",
      "(3873, 227)\n"
     ]
    }
   ],
   "source": [
    "print(x_train.shape)\n",
    "print(x_test.shape)"
   ]
  },
  {
   "cell_type": "code",
   "execution_count": null,
   "id": "8787c367",
   "metadata": {},
   "outputs": [],
   "source": []
  }
 ],
 "metadata": {
  "kernelspec": {
   "display_name": "Python 3 (ipykernel)",
   "language": "python",
   "name": "python3"
  },
  "language_info": {
   "codemirror_mode": {
    "name": "ipython",
    "version": 3
   },
   "file_extension": ".py",
   "mimetype": "text/x-python",
   "name": "python",
   "nbconvert_exporter": "python",
   "pygments_lexer": "ipython3",
   "version": "3.9.12"
  }
 },
 "nbformat": 4,
 "nbformat_minor": 5
}
